<?xml version="1.0" encoding="UTF-8"?>
<!DOCTYPE html PUBLIC "-//W3C//DTD XHTML 1.0 Strict//EN" "http://www.w3.org/TR/xhtml1/DTD/xhtml1-strict.dtd">
<html xmlns="http://www.w3.org/1999/xhtml">
<head>
    <title>下载测试报告</title>
    <meta name="generator" content="HTMLTestRunner 0.8.2"/>
    <meta http-equiv="Content-Type" content="text/html; charset=UTF-8"/>
    
<style type="text/css" media="screen">
body        { font-family: verdana, arial, helvetica, sans-serif; font-size: 80%; }
table       { font-size: 100%; }
pre         { }

/* -- heading ---------------------------------------------------------------------- */
h1 {
	font-size: 16pt;
	color: gray;
}
.heading {
    margin-top: 0ex;
    margin-bottom: 1ex;
}

.heading .attribute {
    margin-top: 1ex;
    margin-bottom: 0;
}

.heading .description {
    margin-top: 4ex;
    margin-bottom: 6ex;
}

/* -- css div popup ------------------------------------------------------------------------ */
a.popup_link {
}

a.popup_link:hover {
    color: red;
}

.popup_window {
    display: none;
    position: relative;
    left: 0px;
    top: 0px;
    /*border: solid #627173 1px; */
    padding: 10px;
    background-color: #E6E6D6;
    font-family: "Lucida Console", "Courier New", Courier, monospace;
    text-align: left;
    font-size: 8pt;
    width: 500px;
}

}
/* -- report ------------------------------------------------------------------------ */
#show_detail_line {
    margin-top: 3ex;
    margin-bottom: 1ex;
}
#result_table {
    width: 80%;
    border-collapse: collapse;
    border: 1px solid #777;
}
#header_row {
    font-weight: bold;
    color: white;
    background-color: #777;
}
#result_table td {
    border: 1px solid #777;
    padding: 2px;
}
#total_row  { font-weight: bold; }
.passClass  { background-color: #6c6; }
.failClass  { background-color: #c60; }
.errorClass { background-color: #c00; }
.passCase   { color: #6c6; }
.failCase   { color: #c60; font-weight: bold; }
.errorCase  { color: #c00; font-weight: bold; }
.hiddenRow  { display: none; }
.testcase   { margin-left: 2em; }


/* -- ending ---------------------------------------------------------------------- */
#ending {
}

</style>

</head>
<body>
<script language="javascript" type="text/javascript"><!--
output_list = Array();

/* level - 0:Summary; 1:Failed; 2:All */
function showCase(level) {
    trs = document.getElementsByTagName("tr");
    for (var i = 0; i < trs.length; i++) {
        tr = trs[i];
        id = tr.id;
        if (id.substr(0,2) == 'ft') {
            if (level < 1) {
                tr.className = 'hiddenRow';
            }
            else {
                tr.className = '';
            }
        }
        if (id.substr(0,2) == 'pt') {
            if (level > 1) {
                tr.className = '';
            }
            else {
                tr.className = 'hiddenRow';
            }
        }
    }
}


function showClassDetail(cid, count) {
    var id_list = Array(count);
    var toHide = 1;
    for (var i = 0; i < count; i++) {
        tid0 = 't' + cid.substr(1) + '.' + (i+1);
        tid = 'f' + tid0;
        tr = document.getElementById(tid);
        if (!tr) {
            tid = 'p' + tid0;
            tr = document.getElementById(tid);
        }
        id_list[i] = tid;
        if (tr.className) {
            toHide = 0;
        }
    }
    for (var i = 0; i < count; i++) {
        tid = id_list[i];
        if (toHide) {
            document.getElementById('div_'+tid).style.display = 'none'
            document.getElementById(tid).className = 'hiddenRow';
        }
        else {
            document.getElementById(tid).className = '';
        }
    }
}


function showTestDetail(div_id){
    var details_div = document.getElementById(div_id)
    var displayState = details_div.style.display
    // alert(displayState)
    if (displayState != 'block' ) {
        displayState = 'block'
        details_div.style.display = 'block'
    }
    else {
        details_div.style.display = 'none'
    }
}


function html_escape(s) {
    s = s.replace(/&/g,'&amp;');
    s = s.replace(/</g,'&lt;');
    s = s.replace(/>/g,'&gt;');
    return s;
}

/* obsoleted by detail in <div>
function showOutput(id, name) {
    var w = window.open("", //url
                    name,
                    "resizable,scrollbars,status,width=800,height=450");
    d = w.document;
    d.write("<pre>");
    d.write(html_escape(output_list[id]));
    d.write("\n");
    d.write("<a href='javascript:window.close()'>close</a>\n");
    d.write("</pre>\n");
    d.close();
}
*/
--></script>

<div class='heading'>
<h1>下载测试报告</h1>
<p class='attribute'><strong>Start Time:</strong> 2018-09-13 18:10:26</p>
<p class='attribute'><strong>Duration:</strong> 0:00:00.105010</p>
<p class='attribute'><strong>Status:</strong> Error 26</p>

<p class='description'>用例执行情况：</p>
</div>



<p id='show_detail_line'>Show
<a href='javascript:showCase(0)'>Summary</a>
<a href='javascript:showCase(1)'>Failed</a>
<a href='javascript:showCase(2)'>All</a>
</p>
<table id='result_table'>
<colgroup>
<col align='left' />
<col align='right' />
<col align='right' />
<col align='right' />
<col align='right' />
<col align='right' />
</colgroup>
<tr id='header_row'>
    <td>Test Group/Test case</td>
    <td>Count</td>
    <td>Pass</td>
    <td>Fail</td>
    <td>Error</td>
    <td>View</td>
</tr>

<tr class='errorClass'>
    <td>test_case.login1_case.Login:  用户登录 </td>
    <td>5</td>
    <td>0</td>
    <td>0</td>
    <td>5</td>
    <td><a href="javascript:showClassDetail('c1',5)">Detail</a></td>
</tr>

<tr id='ft1.1' class='none'>
    <td class='errorCase'><div class='testcase'>test_login1: 用户名、密码为空</div></td>
    <td colspan='5' align='center'>

    <!--css div popup start-->
    <a class="popup_link" onfocus='this.blur();' href="javascript:showTestDetail('div_ft1.1')" >
        error</a>

    <div id='div_ft1.1' class="popup_window">
        <div style='text-align: right; color:red;cursor:pointer'>
        <a onfocus='this.blur();' onclick="document.getElementById('div_ft1.1').style.display = 'none' " >
           [x]</a>
        </div>
        <pre>
        
ft1.1: Traceback (most recent call last):
  File "D:\Python34\lib\site-packages\selenium\webdriver\common\service.py", line 64, in start
    stdout=self.log_file, stderr=self.log_file)
  File "D:\Python34\lib\subprocess.py", line 859, in __init__
    restore_signals, start_new_session)
  File "D:\Python34\lib\subprocess.py", line 1112, in _execute_child
    startupinfo)
FileNotFoundError: [WinError 2] 系统找不到指定的文件。

During handling of the above exception, another exception occurred:

Traceback (most recent call last):
  File "E:\hannn\download5\models\myunit.py", line 12, in setUp
    self.driver = webdriver.Chrome()
  File "D:\Python34\lib\site-packages\selenium\webdriver\chrome\webdriver.py", line 62, in __init__
    self.service.start()
  File "D:\Python34\lib\site-packages\selenium\webdriver\common\service.py", line 71, in start
    os.path.basename(self.path), self.start_error_message)
selenium.common.exceptions.WebDriverException: Message: 'chromedriver' executable needs to be in PATH. Please see https://sites.google.com/a/chromium.org/chromedriver/home

Traceback (most recent call last):
  File "D:\Python34\lib\site-packages\selenium\webdriver\common\service.py", line 64, in start
    stdout=self.log_file, stderr=self.log_file)
  File "D:\Python34\lib\subprocess.py", line 859, in __init__
    restore_signals, start_new_session)
  File "D:\Python34\lib\subprocess.py", line 1112, in _execute_child
    startupinfo)
FileNotFoundError: [WinError 2] 系统找不到指定的文件。

During handling of the above exception, another exception occurred:

Traceback (most recent call last):
  File "E:\hannn\download5\models\myunit.py", line 12, in setUp
    self.driver = webdriver.Chrome()
  File "D:\Python34\lib\site-packages\selenium\webdriver\chrome\webdriver.py", line 62, in __init__
    self.service.start()
  File "D:\Python34\lib\site-packages\selenium\webdriver\common\service.py", line 71, in start
    os.path.basename(self.path), self.start_error_message)
selenium.common.exceptions.WebDriverException: Message: 'chromedriver' executable needs to be in PATH. Please see https://sites.google.com/a/chromium.org/chromedriver/home



        </pre>
    </div>
    <!--css div popup end-->

    </td>
</tr>

<tr id='ft1.2' class='none'>
    <td class='errorCase'><div class='testcase'>test_login2: 用户名正确，密码为空</div></td>
    <td colspan='5' align='center'>

    <!--css div popup start-->
    <a class="popup_link" onfocus='this.blur();' href="javascript:showTestDetail('div_ft1.2')" >
        error</a>

    <div id='div_ft1.2' class="popup_window">
        <div style='text-align: right; color:red;cursor:pointer'>
        <a onfocus='this.blur();' onclick="document.getElementById('div_ft1.2').style.display = 'none' " >
           [x]</a>
        </div>
        <pre>
        
ft1.2: Traceback (most recent call last):
  File "D:\Python34\lib\site-packages\selenium\webdriver\common\service.py", line 64, in start
    stdout=self.log_file, stderr=self.log_file)
  File "D:\Python34\lib\subprocess.py", line 859, in __init__
    restore_signals, start_new_session)
  File "D:\Python34\lib\subprocess.py", line 1112, in _execute_child
    startupinfo)
FileNotFoundError: [WinError 2] 系统找不到指定的文件。

During handling of the above exception, another exception occurred:

Traceback (most recent call last):
  File "E:\hannn\download5\models\myunit.py", line 12, in setUp
    self.driver = webdriver.Chrome()
  File "D:\Python34\lib\site-packages\selenium\webdriver\chrome\webdriver.py", line 62, in __init__
    self.service.start()
  File "D:\Python34\lib\site-packages\selenium\webdriver\common\service.py", line 71, in start
    os.path.basename(self.path), self.start_error_message)
selenium.common.exceptions.WebDriverException: Message: 'chromedriver' executable needs to be in PATH. Please see https://sites.google.com/a/chromium.org/chromedriver/home

Traceback (most recent call last):
  File "D:\Python34\lib\site-packages\selenium\webdriver\common\service.py", line 64, in start
    stdout=self.log_file, stderr=self.log_file)
  File "D:\Python34\lib\subprocess.py", line 859, in __init__
    restore_signals, start_new_session)
  File "D:\Python34\lib\subprocess.py", line 1112, in _execute_child
    startupinfo)
FileNotFoundError: [WinError 2] 系统找不到指定的文件。

During handling of the above exception, another exception occurred:

Traceback (most recent call last):
  File "E:\hannn\download5\models\myunit.py", line 12, in setUp
    self.driver = webdriver.Chrome()
  File "D:\Python34\lib\site-packages\selenium\webdriver\chrome\webdriver.py", line 62, in __init__
    self.service.start()
  File "D:\Python34\lib\site-packages\selenium\webdriver\common\service.py", line 71, in start
    os.path.basename(self.path), self.start_error_message)
selenium.common.exceptions.WebDriverException: Message: 'chromedriver' executable needs to be in PATH. Please see https://sites.google.com/a/chromium.org/chromedriver/home



        </pre>
    </div>
    <!--css div popup end-->

    </td>
</tr>

<tr id='ft1.3' class='none'>
    <td class='errorCase'><div class='testcase'>test_login3: 用户名为空，密码正确</div></td>
    <td colspan='5' align='center'>

    <!--css div popup start-->
    <a class="popup_link" onfocus='this.blur();' href="javascript:showTestDetail('div_ft1.3')" >
        error</a>

    <div id='div_ft1.3' class="popup_window">
        <div style='text-align: right; color:red;cursor:pointer'>
        <a onfocus='this.blur();' onclick="document.getElementById('div_ft1.3').style.display = 'none' " >
           [x]</a>
        </div>
        <pre>
        
ft1.3: Traceback (most recent call last):
  File "D:\Python34\lib\site-packages\selenium\webdriver\common\service.py", line 64, in start
    stdout=self.log_file, stderr=self.log_file)
  File "D:\Python34\lib\subprocess.py", line 859, in __init__
    restore_signals, start_new_session)
  File "D:\Python34\lib\subprocess.py", line 1112, in _execute_child
    startupinfo)
FileNotFoundError: [WinError 2] 系统找不到指定的文件。

During handling of the above exception, another exception occurred:

Traceback (most recent call last):
  File "E:\hannn\download5\models\myunit.py", line 12, in setUp
    self.driver = webdriver.Chrome()
  File "D:\Python34\lib\site-packages\selenium\webdriver\chrome\webdriver.py", line 62, in __init__
    self.service.start()
  File "D:\Python34\lib\site-packages\selenium\webdriver\common\service.py", line 71, in start
    os.path.basename(self.path), self.start_error_message)
selenium.common.exceptions.WebDriverException: Message: 'chromedriver' executable needs to be in PATH. Please see https://sites.google.com/a/chromium.org/chromedriver/home

Traceback (most recent call last):
  File "D:\Python34\lib\site-packages\selenium\webdriver\common\service.py", line 64, in start
    stdout=self.log_file, stderr=self.log_file)
  File "D:\Python34\lib\subprocess.py", line 859, in __init__
    restore_signals, start_new_session)
  File "D:\Python34\lib\subprocess.py", line 1112, in _execute_child
    startupinfo)
FileNotFoundError: [WinError 2] 系统找不到指定的文件。

During handling of the above exception, another exception occurred:

Traceback (most recent call last):
  File "E:\hannn\download5\models\myunit.py", line 12, in setUp
    self.driver = webdriver.Chrome()
  File "D:\Python34\lib\site-packages\selenium\webdriver\chrome\webdriver.py", line 62, in __init__
    self.service.start()
  File "D:\Python34\lib\site-packages\selenium\webdriver\common\service.py", line 71, in start
    os.path.basename(self.path), self.start_error_message)
selenium.common.exceptions.WebDriverException: Message: 'chromedriver' executable needs to be in PATH. Please see https://sites.google.com/a/chromium.org/chromedriver/home



        </pre>
    </div>
    <!--css div popup end-->

    </td>
</tr>

<tr id='ft1.4' class='none'>
    <td class='errorCase'><div class='testcase'>test_login4: 用户名与密码不匹配</div></td>
    <td colspan='5' align='center'>

    <!--css div popup start-->
    <a class="popup_link" onfocus='this.blur();' href="javascript:showTestDetail('div_ft1.4')" >
        error</a>

    <div id='div_ft1.4' class="popup_window">
        <div style='text-align: right; color:red;cursor:pointer'>
        <a onfocus='this.blur();' onclick="document.getElementById('div_ft1.4').style.display = 'none' " >
           [x]</a>
        </div>
        <pre>
        
ft1.4: Traceback (most recent call last):
  File "D:\Python34\lib\site-packages\selenium\webdriver\common\service.py", line 64, in start
    stdout=self.log_file, stderr=self.log_file)
  File "D:\Python34\lib\subprocess.py", line 859, in __init__
    restore_signals, start_new_session)
  File "D:\Python34\lib\subprocess.py", line 1112, in _execute_child
    startupinfo)
FileNotFoundError: [WinError 2] 系统找不到指定的文件。

During handling of the above exception, another exception occurred:

Traceback (most recent call last):
  File "E:\hannn\download5\models\myunit.py", line 12, in setUp
    self.driver = webdriver.Chrome()
  File "D:\Python34\lib\site-packages\selenium\webdriver\chrome\webdriver.py", line 62, in __init__
    self.service.start()
  File "D:\Python34\lib\site-packages\selenium\webdriver\common\service.py", line 71, in start
    os.path.basename(self.path), self.start_error_message)
selenium.common.exceptions.WebDriverException: Message: 'chromedriver' executable needs to be in PATH. Please see https://sites.google.com/a/chromium.org/chromedriver/home

Traceback (most recent call last):
  File "D:\Python34\lib\site-packages\selenium\webdriver\common\service.py", line 64, in start
    stdout=self.log_file, stderr=self.log_file)
  File "D:\Python34\lib\subprocess.py", line 859, in __init__
    restore_signals, start_new_session)
  File "D:\Python34\lib\subprocess.py", line 1112, in _execute_child
    startupinfo)
FileNotFoundError: [WinError 2] 系统找不到指定的文件。

During handling of the above exception, another exception occurred:

Traceback (most recent call last):
  File "E:\hannn\download5\models\myunit.py", line 12, in setUp
    self.driver = webdriver.Chrome()
  File "D:\Python34\lib\site-packages\selenium\webdriver\chrome\webdriver.py", line 62, in __init__
    self.service.start()
  File "D:\Python34\lib\site-packages\selenium\webdriver\common\service.py", line 71, in start
    os.path.basename(self.path), self.start_error_message)
selenium.common.exceptions.WebDriverException: Message: 'chromedriver' executable needs to be in PATH. Please see https://sites.google.com/a/chromium.org/chromedriver/home



        </pre>
    </div>
    <!--css div popup end-->

    </td>
</tr>

<tr id='ft1.5' class='none'>
    <td class='errorCase'><div class='testcase'>test_login5: 用户名密码正确</div></td>
    <td colspan='5' align='center'>

    <!--css div popup start-->
    <a class="popup_link" onfocus='this.blur();' href="javascript:showTestDetail('div_ft1.5')" >
        error</a>

    <div id='div_ft1.5' class="popup_window">
        <div style='text-align: right; color:red;cursor:pointer'>
        <a onfocus='this.blur();' onclick="document.getElementById('div_ft1.5').style.display = 'none' " >
           [x]</a>
        </div>
        <pre>
        
ft1.5: Traceback (most recent call last):
  File "D:\Python34\lib\site-packages\selenium\webdriver\common\service.py", line 64, in start
    stdout=self.log_file, stderr=self.log_file)
  File "D:\Python34\lib\subprocess.py", line 859, in __init__
    restore_signals, start_new_session)
  File "D:\Python34\lib\subprocess.py", line 1112, in _execute_child
    startupinfo)
FileNotFoundError: [WinError 2] 系统找不到指定的文件。

During handling of the above exception, another exception occurred:

Traceback (most recent call last):
  File "E:\hannn\download5\models\myunit.py", line 12, in setUp
    self.driver = webdriver.Chrome()
  File "D:\Python34\lib\site-packages\selenium\webdriver\chrome\webdriver.py", line 62, in __init__
    self.service.start()
  File "D:\Python34\lib\site-packages\selenium\webdriver\common\service.py", line 71, in start
    os.path.basename(self.path), self.start_error_message)
selenium.common.exceptions.WebDriverException: Message: 'chromedriver' executable needs to be in PATH. Please see https://sites.google.com/a/chromium.org/chromedriver/home

Traceback (most recent call last):
  File "D:\Python34\lib\site-packages\selenium\webdriver\common\service.py", line 64, in start
    stdout=self.log_file, stderr=self.log_file)
  File "D:\Python34\lib\subprocess.py", line 859, in __init__
    restore_signals, start_new_session)
  File "D:\Python34\lib\subprocess.py", line 1112, in _execute_child
    startupinfo)
FileNotFoundError: [WinError 2] 系统找不到指定的文件。

During handling of the above exception, another exception occurred:

Traceback (most recent call last):
  File "E:\hannn\download5\models\myunit.py", line 12, in setUp
    self.driver = webdriver.Chrome()
  File "D:\Python34\lib\site-packages\selenium\webdriver\chrome\webdriver.py", line 62, in __init__
    self.service.start()
  File "D:\Python34\lib\site-packages\selenium\webdriver\common\service.py", line 71, in start
    os.path.basename(self.path), self.start_error_message)
selenium.common.exceptions.WebDriverException: Message: 'chromedriver' executable needs to be in PATH. Please see https://sites.google.com/a/chromium.org/chromedriver/home



        </pre>
    </div>
    <!--css div popup end-->

    </td>
</tr>

<tr class='errorClass'>
    <td>test_case.logout_case.Logout:  退出 </td>
    <td>1</td>
    <td>0</td>
    <td>0</td>
    <td>1</td>
    <td><a href="javascript:showClassDetail('c2',1)">Detail</a></td>
</tr>

<tr id='ft2.1' class='none'>
    <td class='errorCase'><div class='testcase'>test_logout: 退出</div></td>
    <td colspan='5' align='center'>

    <!--css div popup start-->
    <a class="popup_link" onfocus='this.blur();' href="javascript:showTestDetail('div_ft2.1')" >
        error</a>

    <div id='div_ft2.1' class="popup_window">
        <div style='text-align: right; color:red;cursor:pointer'>
        <a onfocus='this.blur();' onclick="document.getElementById('div_ft2.1').style.display = 'none' " >
           [x]</a>
        </div>
        <pre>
        
ft2.1: Traceback (most recent call last):
  File "D:\Python34\lib\site-packages\selenium\webdriver\common\service.py", line 64, in start
    stdout=self.log_file, stderr=self.log_file)
  File "D:\Python34\lib\subprocess.py", line 859, in __init__
    restore_signals, start_new_session)
  File "D:\Python34\lib\subprocess.py", line 1112, in _execute_child
    startupinfo)
FileNotFoundError: [WinError 2] 系统找不到指定的文件。

During handling of the above exception, another exception occurred:

Traceback (most recent call last):
  File "E:\hannn\download5\models\myunit.py", line 12, in setUp
    self.driver = webdriver.Chrome()
  File "D:\Python34\lib\site-packages\selenium\webdriver\chrome\webdriver.py", line 62, in __init__
    self.service.start()
  File "D:\Python34\lib\site-packages\selenium\webdriver\common\service.py", line 71, in start
    os.path.basename(self.path), self.start_error_message)
selenium.common.exceptions.WebDriverException: Message: 'chromedriver' executable needs to be in PATH. Please see https://sites.google.com/a/chromium.org/chromedriver/home

Traceback (most recent call last):
  File "D:\Python34\lib\site-packages\selenium\webdriver\common\service.py", line 64, in start
    stdout=self.log_file, stderr=self.log_file)
  File "D:\Python34\lib\subprocess.py", line 859, in __init__
    restore_signals, start_new_session)
  File "D:\Python34\lib\subprocess.py", line 1112, in _execute_child
    startupinfo)
FileNotFoundError: [WinError 2] 系统找不到指定的文件。

During handling of the above exception, another exception occurred:

Traceback (most recent call last):
  File "E:\hannn\download5\models\myunit.py", line 12, in setUp
    self.driver = webdriver.Chrome()
  File "D:\Python34\lib\site-packages\selenium\webdriver\chrome\webdriver.py", line 62, in __init__
    self.service.start()
  File "D:\Python34\lib\site-packages\selenium\webdriver\common\service.py", line 71, in start
    os.path.basename(self.path), self.start_error_message)
selenium.common.exceptions.WebDriverException: Message: 'chromedriver' executable needs to be in PATH. Please see https://sites.google.com/a/chromium.org/chromedriver/home



        </pre>
    </div>
    <!--css div popup end-->

    </td>
</tr>

<tr class='errorClass'>
    <td>test_case.search_case.Search:  首页-搜索 </td>
    <td>1</td>
    <td>0</td>
    <td>0</td>
    <td>1</td>
    <td><a href="javascript:showClassDetail('c3',1)">Detail</a></td>
</tr>

<tr id='ft3.1' class='none'>
    <td class='errorCase'><div class='testcase'>test_search: ' 搜索</div></td>
    <td colspan='5' align='center'>

    <!--css div popup start-->
    <a class="popup_link" onfocus='this.blur();' href="javascript:showTestDetail('div_ft3.1')" >
        error</a>

    <div id='div_ft3.1' class="popup_window">
        <div style='text-align: right; color:red;cursor:pointer'>
        <a onfocus='this.blur();' onclick="document.getElementById('div_ft3.1').style.display = 'none' " >
           [x]</a>
        </div>
        <pre>
        
ft3.1: Traceback (most recent call last):
  File "D:\Python34\lib\site-packages\selenium\webdriver\common\service.py", line 64, in start
    stdout=self.log_file, stderr=self.log_file)
  File "D:\Python34\lib\subprocess.py", line 859, in __init__
    restore_signals, start_new_session)
  File "D:\Python34\lib\subprocess.py", line 1112, in _execute_child
    startupinfo)
FileNotFoundError: [WinError 2] 系统找不到指定的文件。

During handling of the above exception, another exception occurred:

Traceback (most recent call last):
  File "E:\hannn\download5\models\myunit.py", line 12, in setUp
    self.driver = webdriver.Chrome()
  File "D:\Python34\lib\site-packages\selenium\webdriver\chrome\webdriver.py", line 62, in __init__
    self.service.start()
  File "D:\Python34\lib\site-packages\selenium\webdriver\common\service.py", line 71, in start
    os.path.basename(self.path), self.start_error_message)
selenium.common.exceptions.WebDriverException: Message: 'chromedriver' executable needs to be in PATH. Please see https://sites.google.com/a/chromium.org/chromedriver/home

Traceback (most recent call last):
  File "D:\Python34\lib\site-packages\selenium\webdriver\common\service.py", line 64, in start
    stdout=self.log_file, stderr=self.log_file)
  File "D:\Python34\lib\subprocess.py", line 859, in __init__
    restore_signals, start_new_session)
  File "D:\Python34\lib\subprocess.py", line 1112, in _execute_child
    startupinfo)
FileNotFoundError: [WinError 2] 系统找不到指定的文件。

During handling of the above exception, another exception occurred:

Traceback (most recent call last):
  File "E:\hannn\download5\models\myunit.py", line 12, in setUp
    self.driver = webdriver.Chrome()
  File "D:\Python34\lib\site-packages\selenium\webdriver\chrome\webdriver.py", line 62, in __init__
    self.service.start()
  File "D:\Python34\lib\site-packages\selenium\webdriver\common\service.py", line 71, in start
    os.path.basename(self.path), self.start_error_message)
selenium.common.exceptions.WebDriverException: Message: 'chromedriver' executable needs to be in PATH. Please see https://sites.google.com/a/chromium.org/chromedriver/home



        </pre>
    </div>
    <!--css div popup end-->

    </td>
</tr>

<tr class='errorClass'>
    <td>test_case.report_case.Report:  举报 </td>
    <td>3</td>
    <td>0</td>
    <td>0</td>
    <td>3</td>
    <td><a href="javascript:showClassDetail('c4',3)">Detail</a></td>
</tr>

<tr id='ft4.1' class='none'>
    <td class='errorCase'><div class='testcase'>test_report1: 未下载举报</div></td>
    <td colspan='5' align='center'>

    <!--css div popup start-->
    <a class="popup_link" onfocus='this.blur();' href="javascript:showTestDetail('div_ft4.1')" >
        error</a>

    <div id='div_ft4.1' class="popup_window">
        <div style='text-align: right; color:red;cursor:pointer'>
        <a onfocus='this.blur();' onclick="document.getElementById('div_ft4.1').style.display = 'none' " >
           [x]</a>
        </div>
        <pre>
        
ft4.1: Traceback (most recent call last):
  File "D:\Python34\lib\site-packages\selenium\webdriver\common\service.py", line 64, in start
    stdout=self.log_file, stderr=self.log_file)
  File "D:\Python34\lib\subprocess.py", line 859, in __init__
    restore_signals, start_new_session)
  File "D:\Python34\lib\subprocess.py", line 1112, in _execute_child
    startupinfo)
FileNotFoundError: [WinError 2] 系统找不到指定的文件。

During handling of the above exception, another exception occurred:

Traceback (most recent call last):
  File "E:\hannn\download5\models\myunit.py", line 12, in setUp
    self.driver = webdriver.Chrome()
  File "D:\Python34\lib\site-packages\selenium\webdriver\chrome\webdriver.py", line 62, in __init__
    self.service.start()
  File "D:\Python34\lib\site-packages\selenium\webdriver\common\service.py", line 71, in start
    os.path.basename(self.path), self.start_error_message)
selenium.common.exceptions.WebDriverException: Message: 'chromedriver' executable needs to be in PATH. Please see https://sites.google.com/a/chromium.org/chromedriver/home

Traceback (most recent call last):
  File "D:\Python34\lib\site-packages\selenium\webdriver\common\service.py", line 64, in start
    stdout=self.log_file, stderr=self.log_file)
  File "D:\Python34\lib\subprocess.py", line 859, in __init__
    restore_signals, start_new_session)
  File "D:\Python34\lib\subprocess.py", line 1112, in _execute_child
    startupinfo)
FileNotFoundError: [WinError 2] 系统找不到指定的文件。

During handling of the above exception, another exception occurred:

Traceback (most recent call last):
  File "E:\hannn\download5\models\myunit.py", line 12, in setUp
    self.driver = webdriver.Chrome()
  File "D:\Python34\lib\site-packages\selenium\webdriver\chrome\webdriver.py", line 62, in __init__
    self.service.start()
  File "D:\Python34\lib\site-packages\selenium\webdriver\common\service.py", line 71, in start
    os.path.basename(self.path), self.start_error_message)
selenium.common.exceptions.WebDriverException: Message: 'chromedriver' executable needs to be in PATH. Please see https://sites.google.com/a/chromium.org/chromedriver/home



        </pre>
    </div>
    <!--css div popup end-->

    </td>
</tr>

<tr id='ft4.2' class='none'>
    <td class='errorCase'><div class='testcase'>test_report2: 举报自己的资源</div></td>
    <td colspan='5' align='center'>

    <!--css div popup start-->
    <a class="popup_link" onfocus='this.blur();' href="javascript:showTestDetail('div_ft4.2')" >
        error</a>

    <div id='div_ft4.2' class="popup_window">
        <div style='text-align: right; color:red;cursor:pointer'>
        <a onfocus='this.blur();' onclick="document.getElementById('div_ft4.2').style.display = 'none' " >
           [x]</a>
        </div>
        <pre>
        
ft4.2: Traceback (most recent call last):
  File "D:\Python34\lib\site-packages\selenium\webdriver\common\service.py", line 64, in start
    stdout=self.log_file, stderr=self.log_file)
  File "D:\Python34\lib\subprocess.py", line 859, in __init__
    restore_signals, start_new_session)
  File "D:\Python34\lib\subprocess.py", line 1112, in _execute_child
    startupinfo)
FileNotFoundError: [WinError 2] 系统找不到指定的文件。

During handling of the above exception, another exception occurred:

Traceback (most recent call last):
  File "E:\hannn\download5\models\myunit.py", line 12, in setUp
    self.driver = webdriver.Chrome()
  File "D:\Python34\lib\site-packages\selenium\webdriver\chrome\webdriver.py", line 62, in __init__
    self.service.start()
  File "D:\Python34\lib\site-packages\selenium\webdriver\common\service.py", line 71, in start
    os.path.basename(self.path), self.start_error_message)
selenium.common.exceptions.WebDriverException: Message: 'chromedriver' executable needs to be in PATH. Please see https://sites.google.com/a/chromium.org/chromedriver/home

Traceback (most recent call last):
  File "D:\Python34\lib\site-packages\selenium\webdriver\common\service.py", line 64, in start
    stdout=self.log_file, stderr=self.log_file)
  File "D:\Python34\lib\subprocess.py", line 859, in __init__
    restore_signals, start_new_session)
  File "D:\Python34\lib\subprocess.py", line 1112, in _execute_child
    startupinfo)
FileNotFoundError: [WinError 2] 系统找不到指定的文件。

During handling of the above exception, another exception occurred:

Traceback (most recent call last):
  File "E:\hannn\download5\models\myunit.py", line 12, in setUp
    self.driver = webdriver.Chrome()
  File "D:\Python34\lib\site-packages\selenium\webdriver\chrome\webdriver.py", line 62, in __init__
    self.service.start()
  File "D:\Python34\lib\site-packages\selenium\webdriver\common\service.py", line 71, in start
    os.path.basename(self.path), self.start_error_message)
selenium.common.exceptions.WebDriverException: Message: 'chromedriver' executable needs to be in PATH. Please see https://sites.google.com/a/chromium.org/chromedriver/home



        </pre>
    </div>
    <!--css div popup end-->

    </td>
</tr>

<tr id='ft4.3' class='none'>
    <td class='errorCase'><div class='testcase'>test_report3: 举报后点击取消</div></td>
    <td colspan='5' align='center'>

    <!--css div popup start-->
    <a class="popup_link" onfocus='this.blur();' href="javascript:showTestDetail('div_ft4.3')" >
        error</a>

    <div id='div_ft4.3' class="popup_window">
        <div style='text-align: right; color:red;cursor:pointer'>
        <a onfocus='this.blur();' onclick="document.getElementById('div_ft4.3').style.display = 'none' " >
           [x]</a>
        </div>
        <pre>
        
ft4.3: Traceback (most recent call last):
  File "D:\Python34\lib\site-packages\selenium\webdriver\common\service.py", line 64, in start
    stdout=self.log_file, stderr=self.log_file)
  File "D:\Python34\lib\subprocess.py", line 859, in __init__
    restore_signals, start_new_session)
  File "D:\Python34\lib\subprocess.py", line 1112, in _execute_child
    startupinfo)
FileNotFoundError: [WinError 2] 系统找不到指定的文件。

During handling of the above exception, another exception occurred:

Traceback (most recent call last):
  File "E:\hannn\download5\models\myunit.py", line 12, in setUp
    self.driver = webdriver.Chrome()
  File "D:\Python34\lib\site-packages\selenium\webdriver\chrome\webdriver.py", line 62, in __init__
    self.service.start()
  File "D:\Python34\lib\site-packages\selenium\webdriver\common\service.py", line 71, in start
    os.path.basename(self.path), self.start_error_message)
selenium.common.exceptions.WebDriverException: Message: 'chromedriver' executable needs to be in PATH. Please see https://sites.google.com/a/chromium.org/chromedriver/home

Traceback (most recent call last):
  File "D:\Python34\lib\site-packages\selenium\webdriver\common\service.py", line 64, in start
    stdout=self.log_file, stderr=self.log_file)
  File "D:\Python34\lib\subprocess.py", line 859, in __init__
    restore_signals, start_new_session)
  File "D:\Python34\lib\subprocess.py", line 1112, in _execute_child
    startupinfo)
FileNotFoundError: [WinError 2] 系统找不到指定的文件。

During handling of the above exception, another exception occurred:

Traceback (most recent call last):
  File "E:\hannn\download5\models\myunit.py", line 12, in setUp
    self.driver = webdriver.Chrome()
  File "D:\Python34\lib\site-packages\selenium\webdriver\chrome\webdriver.py", line 62, in __init__
    self.service.start()
  File "D:\Python34\lib\site-packages\selenium\webdriver\common\service.py", line 71, in start
    os.path.basename(self.path), self.start_error_message)
selenium.common.exceptions.WebDriverException: Message: 'chromedriver' executable needs to be in PATH. Please see https://sites.google.com/a/chromium.org/chromedriver/home



        </pre>
    </div>
    <!--css div popup end-->

    </td>
</tr>

<tr class='errorClass'>
    <td>test_case.collect_case.Collect</td>
    <td>1</td>
    <td>0</td>
    <td>0</td>
    <td>1</td>
    <td><a href="javascript:showClassDetail('c5',1)">Detail</a></td>
</tr>

<tr id='ft5.1' class='none'>
    <td class='errorCase'><div class='testcase'>test_collect: 资源收藏</div></td>
    <td colspan='5' align='center'>

    <!--css div popup start-->
    <a class="popup_link" onfocus='this.blur();' href="javascript:showTestDetail('div_ft5.1')" >
        error</a>

    <div id='div_ft5.1' class="popup_window">
        <div style='text-align: right; color:red;cursor:pointer'>
        <a onfocus='this.blur();' onclick="document.getElementById('div_ft5.1').style.display = 'none' " >
           [x]</a>
        </div>
        <pre>
        
ft5.1: Traceback (most recent call last):
  File "D:\Python34\lib\site-packages\selenium\webdriver\common\service.py", line 64, in start
    stdout=self.log_file, stderr=self.log_file)
  File "D:\Python34\lib\subprocess.py", line 859, in __init__
    restore_signals, start_new_session)
  File "D:\Python34\lib\subprocess.py", line 1112, in _execute_child
    startupinfo)
FileNotFoundError: [WinError 2] 系统找不到指定的文件。

During handling of the above exception, another exception occurred:

Traceback (most recent call last):
  File "E:\hannn\download5\models\myunit.py", line 12, in setUp
    self.driver = webdriver.Chrome()
  File "D:\Python34\lib\site-packages\selenium\webdriver\chrome\webdriver.py", line 62, in __init__
    self.service.start()
  File "D:\Python34\lib\site-packages\selenium\webdriver\common\service.py", line 71, in start
    os.path.basename(self.path), self.start_error_message)
selenium.common.exceptions.WebDriverException: Message: 'chromedriver' executable needs to be in PATH. Please see https://sites.google.com/a/chromium.org/chromedriver/home

Traceback (most recent call last):
  File "D:\Python34\lib\site-packages\selenium\webdriver\common\service.py", line 64, in start
    stdout=self.log_file, stderr=self.log_file)
  File "D:\Python34\lib\subprocess.py", line 859, in __init__
    restore_signals, start_new_session)
  File "D:\Python34\lib\subprocess.py", line 1112, in _execute_child
    startupinfo)
FileNotFoundError: [WinError 2] 系统找不到指定的文件。

During handling of the above exception, another exception occurred:

Traceback (most recent call last):
  File "E:\hannn\download5\models\myunit.py", line 12, in setUp
    self.driver = webdriver.Chrome()
  File "D:\Python34\lib\site-packages\selenium\webdriver\chrome\webdriver.py", line 62, in __init__
    self.service.start()
  File "D:\Python34\lib\site-packages\selenium\webdriver\common\service.py", line 71, in start
    os.path.basename(self.path), self.start_error_message)
selenium.common.exceptions.WebDriverException: Message: 'chromedriver' executable needs to be in PATH. Please see https://sites.google.com/a/chromium.org/chromedriver/home



        </pre>
    </div>
    <!--css div popup end-->

    </td>
</tr>

<tr class='errorClass'>
    <td>test_case.nocollect_case.Nocollect</td>
    <td>1</td>
    <td>0</td>
    <td>0</td>
    <td>1</td>
    <td><a href="javascript:showClassDetail('c6',1)">Detail</a></td>
</tr>

<tr id='ft6.1' class='none'>
    <td class='errorCase'><div class='testcase'>test_nocollect: 取消收藏</div></td>
    <td colspan='5' align='center'>

    <!--css div popup start-->
    <a class="popup_link" onfocus='this.blur();' href="javascript:showTestDetail('div_ft6.1')" >
        error</a>

    <div id='div_ft6.1' class="popup_window">
        <div style='text-align: right; color:red;cursor:pointer'>
        <a onfocus='this.blur();' onclick="document.getElementById('div_ft6.1').style.display = 'none' " >
           [x]</a>
        </div>
        <pre>
        
ft6.1: Traceback (most recent call last):
  File "D:\Python34\lib\site-packages\selenium\webdriver\common\service.py", line 64, in start
    stdout=self.log_file, stderr=self.log_file)
  File "D:\Python34\lib\subprocess.py", line 859, in __init__
    restore_signals, start_new_session)
  File "D:\Python34\lib\subprocess.py", line 1112, in _execute_child
    startupinfo)
FileNotFoundError: [WinError 2] 系统找不到指定的文件。

During handling of the above exception, another exception occurred:

Traceback (most recent call last):
  File "E:\hannn\download5\models\myunit.py", line 12, in setUp
    self.driver = webdriver.Chrome()
  File "D:\Python34\lib\site-packages\selenium\webdriver\chrome\webdriver.py", line 62, in __init__
    self.service.start()
  File "D:\Python34\lib\site-packages\selenium\webdriver\common\service.py", line 71, in start
    os.path.basename(self.path), self.start_error_message)
selenium.common.exceptions.WebDriverException: Message: 'chromedriver' executable needs to be in PATH. Please see https://sites.google.com/a/chromium.org/chromedriver/home

Traceback (most recent call last):
  File "D:\Python34\lib\site-packages\selenium\webdriver\common\service.py", line 64, in start
    stdout=self.log_file, stderr=self.log_file)
  File "D:\Python34\lib\subprocess.py", line 859, in __init__
    restore_signals, start_new_session)
  File "D:\Python34\lib\subprocess.py", line 1112, in _execute_child
    startupinfo)
FileNotFoundError: [WinError 2] 系统找不到指定的文件。

During handling of the above exception, another exception occurred:

Traceback (most recent call last):
  File "E:\hannn\download5\models\myunit.py", line 12, in setUp
    self.driver = webdriver.Chrome()
  File "D:\Python34\lib\site-packages\selenium\webdriver\chrome\webdriver.py", line 62, in __init__
    self.service.start()
  File "D:\Python34\lib\site-packages\selenium\webdriver\common\service.py", line 71, in start
    os.path.basename(self.path), self.start_error_message)
selenium.common.exceptions.WebDriverException: Message: 'chromedriver' executable needs to be in PATH. Please see https://sites.google.com/a/chromium.org/chromedriver/home



        </pre>
    </div>
    <!--css div popup end-->

    </td>
</tr>

<tr class='errorClass'>
    <td>test_case.download_case.Download:  普通用户下载 </td>
    <td>5</td>
    <td>0</td>
    <td>0</td>
    <td>5</td>
    <td><a href="javascript:showClassDetail('c7',5)">Detail</a></td>
</tr>

<tr id='ft7.1' class='none'>
    <td class='errorCase'><div class='testcase'>test_download1: 积分不足有剩余C币</div></td>
    <td colspan='5' align='center'>

    <!--css div popup start-->
    <a class="popup_link" onfocus='this.blur();' href="javascript:showTestDetail('div_ft7.1')" >
        error</a>

    <div id='div_ft7.1' class="popup_window">
        <div style='text-align: right; color:red;cursor:pointer'>
        <a onfocus='this.blur();' onclick="document.getElementById('div_ft7.1').style.display = 'none' " >
           [x]</a>
        </div>
        <pre>
        
ft7.1: Traceback (most recent call last):
  File "D:\Python34\lib\site-packages\selenium\webdriver\common\service.py", line 64, in start
    stdout=self.log_file, stderr=self.log_file)
  File "D:\Python34\lib\subprocess.py", line 859, in __init__
    restore_signals, start_new_session)
  File "D:\Python34\lib\subprocess.py", line 1112, in _execute_child
    startupinfo)
FileNotFoundError: [WinError 2] 系统找不到指定的文件。

During handling of the above exception, another exception occurred:

Traceback (most recent call last):
  File "E:\hannn\download5\models\myunit.py", line 12, in setUp
    self.driver = webdriver.Chrome()
  File "D:\Python34\lib\site-packages\selenium\webdriver\chrome\webdriver.py", line 62, in __init__
    self.service.start()
  File "D:\Python34\lib\site-packages\selenium\webdriver\common\service.py", line 71, in start
    os.path.basename(self.path), self.start_error_message)
selenium.common.exceptions.WebDriverException: Message: 'chromedriver' executable needs to be in PATH. Please see https://sites.google.com/a/chromium.org/chromedriver/home

Traceback (most recent call last):
  File "D:\Python34\lib\site-packages\selenium\webdriver\common\service.py", line 64, in start
    stdout=self.log_file, stderr=self.log_file)
  File "D:\Python34\lib\subprocess.py", line 859, in __init__
    restore_signals, start_new_session)
  File "D:\Python34\lib\subprocess.py", line 1112, in _execute_child
    startupinfo)
FileNotFoundError: [WinError 2] 系统找不到指定的文件。

During handling of the above exception, another exception occurred:

Traceback (most recent call last):
  File "E:\hannn\download5\models\myunit.py", line 12, in setUp
    self.driver = webdriver.Chrome()
  File "D:\Python34\lib\site-packages\selenium\webdriver\chrome\webdriver.py", line 62, in __init__
    self.service.start()
  File "D:\Python34\lib\site-packages\selenium\webdriver\common\service.py", line 71, in start
    os.path.basename(self.path), self.start_error_message)
selenium.common.exceptions.WebDriverException: Message: 'chromedriver' executable needs to be in PATH. Please see https://sites.google.com/a/chromium.org/chromedriver/home



        </pre>
    </div>
    <!--css div popup end-->

    </td>
</tr>

<tr id='ft7.2' class='none'>
    <td class='errorCase'><div class='testcase'>test_download2: 资源大于0，积分和C币等于0</div></td>
    <td colspan='5' align='center'>

    <!--css div popup start-->
    <a class="popup_link" onfocus='this.blur();' href="javascript:showTestDetail('div_ft7.2')" >
        error</a>

    <div id='div_ft7.2' class="popup_window">
        <div style='text-align: right; color:red;cursor:pointer'>
        <a onfocus='this.blur();' onclick="document.getElementById('div_ft7.2').style.display = 'none' " >
           [x]</a>
        </div>
        <pre>
        
ft7.2: Traceback (most recent call last):
  File "D:\Python34\lib\site-packages\selenium\webdriver\common\service.py", line 64, in start
    stdout=self.log_file, stderr=self.log_file)
  File "D:\Python34\lib\subprocess.py", line 859, in __init__
    restore_signals, start_new_session)
  File "D:\Python34\lib\subprocess.py", line 1112, in _execute_child
    startupinfo)
FileNotFoundError: [WinError 2] 系统找不到指定的文件。

During handling of the above exception, another exception occurred:

Traceback (most recent call last):
  File "E:\hannn\download5\models\myunit.py", line 12, in setUp
    self.driver = webdriver.Chrome()
  File "D:\Python34\lib\site-packages\selenium\webdriver\chrome\webdriver.py", line 62, in __init__
    self.service.start()
  File "D:\Python34\lib\site-packages\selenium\webdriver\common\service.py", line 71, in start
    os.path.basename(self.path), self.start_error_message)
selenium.common.exceptions.WebDriverException: Message: 'chromedriver' executable needs to be in PATH. Please see https://sites.google.com/a/chromium.org/chromedriver/home

Traceback (most recent call last):
  File "D:\Python34\lib\site-packages\selenium\webdriver\common\service.py", line 64, in start
    stdout=self.log_file, stderr=self.log_file)
  File "D:\Python34\lib\subprocess.py", line 859, in __init__
    restore_signals, start_new_session)
  File "D:\Python34\lib\subprocess.py", line 1112, in _execute_child
    startupinfo)
FileNotFoundError: [WinError 2] 系统找不到指定的文件。

During handling of the above exception, another exception occurred:

Traceback (most recent call last):
  File "E:\hannn\download5\models\myunit.py", line 12, in setUp
    self.driver = webdriver.Chrome()
  File "D:\Python34\lib\site-packages\selenium\webdriver\chrome\webdriver.py", line 62, in __init__
    self.service.start()
  File "D:\Python34\lib\site-packages\selenium\webdriver\common\service.py", line 71, in start
    os.path.basename(self.path), self.start_error_message)
selenium.common.exceptions.WebDriverException: Message: 'chromedriver' executable needs to be in PATH. Please see https://sites.google.com/a/chromium.org/chromedriver/home



        </pre>
    </div>
    <!--css div popup end-->

    </td>
</tr>

<tr id='ft7.3' class='none'>
    <td class='errorCase'><div class='testcase'>test_download3: 下载自己的资源</div></td>
    <td colspan='5' align='center'>

    <!--css div popup start-->
    <a class="popup_link" onfocus='this.blur();' href="javascript:showTestDetail('div_ft7.3')" >
        error</a>

    <div id='div_ft7.3' class="popup_window">
        <div style='text-align: right; color:red;cursor:pointer'>
        <a onfocus='this.blur();' onclick="document.getElementById('div_ft7.3').style.display = 'none' " >
           [x]</a>
        </div>
        <pre>
        
ft7.3: Traceback (most recent call last):
  File "D:\Python34\lib\site-packages\selenium\webdriver\common\service.py", line 64, in start
    stdout=self.log_file, stderr=self.log_file)
  File "D:\Python34\lib\subprocess.py", line 859, in __init__
    restore_signals, start_new_session)
  File "D:\Python34\lib\subprocess.py", line 1112, in _execute_child
    startupinfo)
FileNotFoundError: [WinError 2] 系统找不到指定的文件。

During handling of the above exception, another exception occurred:

Traceback (most recent call last):
  File "E:\hannn\download5\models\myunit.py", line 12, in setUp
    self.driver = webdriver.Chrome()
  File "D:\Python34\lib\site-packages\selenium\webdriver\chrome\webdriver.py", line 62, in __init__
    self.service.start()
  File "D:\Python34\lib\site-packages\selenium\webdriver\common\service.py", line 71, in start
    os.path.basename(self.path), self.start_error_message)
selenium.common.exceptions.WebDriverException: Message: 'chromedriver' executable needs to be in PATH. Please see https://sites.google.com/a/chromium.org/chromedriver/home

Traceback (most recent call last):
  File "D:\Python34\lib\site-packages\selenium\webdriver\common\service.py", line 64, in start
    stdout=self.log_file, stderr=self.log_file)
  File "D:\Python34\lib\subprocess.py", line 859, in __init__
    restore_signals, start_new_session)
  File "D:\Python34\lib\subprocess.py", line 1112, in _execute_child
    startupinfo)
FileNotFoundError: [WinError 2] 系统找不到指定的文件。

During handling of the above exception, another exception occurred:

Traceback (most recent call last):
  File "E:\hannn\download5\models\myunit.py", line 12, in setUp
    self.driver = webdriver.Chrome()
  File "D:\Python34\lib\site-packages\selenium\webdriver\chrome\webdriver.py", line 62, in __init__
    self.service.start()
  File "D:\Python34\lib\site-packages\selenium\webdriver\common\service.py", line 71, in start
    os.path.basename(self.path), self.start_error_message)
selenium.common.exceptions.WebDriverException: Message: 'chromedriver' executable needs to be in PATH. Please see https://sites.google.com/a/chromium.org/chromedriver/home



        </pre>
    </div>
    <!--css div popup end-->

    </td>
</tr>

<tr id='ft7.4' class='none'>
    <td class='errorCase'><div class='testcase'>test_download4: 资源/积分/C币 == 0</div></td>
    <td colspan='5' align='center'>

    <!--css div popup start-->
    <a class="popup_link" onfocus='this.blur();' href="javascript:showTestDetail('div_ft7.4')" >
        error</a>

    <div id='div_ft7.4' class="popup_window">
        <div style='text-align: right; color:red;cursor:pointer'>
        <a onfocus='this.blur();' onclick="document.getElementById('div_ft7.4').style.display = 'none' " >
           [x]</a>
        </div>
        <pre>
        
ft7.4: Traceback (most recent call last):
  File "D:\Python34\lib\site-packages\selenium\webdriver\common\service.py", line 64, in start
    stdout=self.log_file, stderr=self.log_file)
  File "D:\Python34\lib\subprocess.py", line 859, in __init__
    restore_signals, start_new_session)
  File "D:\Python34\lib\subprocess.py", line 1112, in _execute_child
    startupinfo)
FileNotFoundError: [WinError 2] 系统找不到指定的文件。

During handling of the above exception, another exception occurred:

Traceback (most recent call last):
  File "E:\hannn\download5\models\myunit.py", line 12, in setUp
    self.driver = webdriver.Chrome()
  File "D:\Python34\lib\site-packages\selenium\webdriver\chrome\webdriver.py", line 62, in __init__
    self.service.start()
  File "D:\Python34\lib\site-packages\selenium\webdriver\common\service.py", line 71, in start
    os.path.basename(self.path), self.start_error_message)
selenium.common.exceptions.WebDriverException: Message: 'chromedriver' executable needs to be in PATH. Please see https://sites.google.com/a/chromium.org/chromedriver/home

Traceback (most recent call last):
  File "D:\Python34\lib\site-packages\selenium\webdriver\common\service.py", line 64, in start
    stdout=self.log_file, stderr=self.log_file)
  File "D:\Python34\lib\subprocess.py", line 859, in __init__
    restore_signals, start_new_session)
  File "D:\Python34\lib\subprocess.py", line 1112, in _execute_child
    startupinfo)
FileNotFoundError: [WinError 2] 系统找不到指定的文件。

During handling of the above exception, another exception occurred:

Traceback (most recent call last):
  File "E:\hannn\download5\models\myunit.py", line 12, in setUp
    self.driver = webdriver.Chrome()
  File "D:\Python34\lib\site-packages\selenium\webdriver\chrome\webdriver.py", line 62, in __init__
    self.service.start()
  File "D:\Python34\lib\site-packages\selenium\webdriver\common\service.py", line 71, in start
    os.path.basename(self.path), self.start_error_message)
selenium.common.exceptions.WebDriverException: Message: 'chromedriver' executable needs to be in PATH. Please see https://sites.google.com/a/chromium.org/chromedriver/home



        </pre>
    </div>
    <!--css div popup end-->

    </td>
</tr>

<tr id='ft7.5' class='none'>
    <td class='errorCase'><div class='testcase'>test_download5: 重复下载资源-未评论</div></td>
    <td colspan='5' align='center'>

    <!--css div popup start-->
    <a class="popup_link" onfocus='this.blur();' href="javascript:showTestDetail('div_ft7.5')" >
        error</a>

    <div id='div_ft7.5' class="popup_window">
        <div style='text-align: right; color:red;cursor:pointer'>
        <a onfocus='this.blur();' onclick="document.getElementById('div_ft7.5').style.display = 'none' " >
           [x]</a>
        </div>
        <pre>
        
ft7.5: Traceback (most recent call last):
  File "D:\Python34\lib\site-packages\selenium\webdriver\common\service.py", line 64, in start
    stdout=self.log_file, stderr=self.log_file)
  File "D:\Python34\lib\subprocess.py", line 859, in __init__
    restore_signals, start_new_session)
  File "D:\Python34\lib\subprocess.py", line 1112, in _execute_child
    startupinfo)
FileNotFoundError: [WinError 2] 系统找不到指定的文件。

During handling of the above exception, another exception occurred:

Traceback (most recent call last):
  File "E:\hannn\download5\models\myunit.py", line 12, in setUp
    self.driver = webdriver.Chrome()
  File "D:\Python34\lib\site-packages\selenium\webdriver\chrome\webdriver.py", line 62, in __init__
    self.service.start()
  File "D:\Python34\lib\site-packages\selenium\webdriver\common\service.py", line 71, in start
    os.path.basename(self.path), self.start_error_message)
selenium.common.exceptions.WebDriverException: Message: 'chromedriver' executable needs to be in PATH. Please see https://sites.google.com/a/chromium.org/chromedriver/home

Traceback (most recent call last):
  File "D:\Python34\lib\site-packages\selenium\webdriver\common\service.py", line 64, in start
    stdout=self.log_file, stderr=self.log_file)
  File "D:\Python34\lib\subprocess.py", line 859, in __init__
    restore_signals, start_new_session)
  File "D:\Python34\lib\subprocess.py", line 1112, in _execute_child
    startupinfo)
FileNotFoundError: [WinError 2] 系统找不到指定的文件。

During handling of the above exception, another exception occurred:

Traceback (most recent call last):
  File "E:\hannn\download5\models\myunit.py", line 12, in setUp
    self.driver = webdriver.Chrome()
  File "D:\Python34\lib\site-packages\selenium\webdriver\chrome\webdriver.py", line 62, in __init__
    self.service.start()
  File "D:\Python34\lib\site-packages\selenium\webdriver\common\service.py", line 71, in start
    os.path.basename(self.path), self.start_error_message)
selenium.common.exceptions.WebDriverException: Message: 'chromedriver' executable needs to be in PATH. Please see https://sites.google.com/a/chromium.org/chromedriver/home



        </pre>
    </div>
    <!--css div popup end-->

    </td>
</tr>

<tr class='errorClass'>
    <td>test_case.downloadvip_case.DownloadVip:  VIP下载 </td>
    <td>2</td>
    <td>0</td>
    <td>0</td>
    <td>2</td>
    <td><a href="javascript:showClassDetail('c8',2)">Detail</a></td>
</tr>

<tr id='ft8.1' class='none'>
    <td class='errorCase'><div class='testcase'>test_downloadg_vip: 跟随菜单VIP按钮</div></td>
    <td colspan='5' align='center'>

    <!--css div popup start-->
    <a class="popup_link" onfocus='this.blur();' href="javascript:showTestDetail('div_ft8.1')" >
        error</a>

    <div id='div_ft8.1' class="popup_window">
        <div style='text-align: right; color:red;cursor:pointer'>
        <a onfocus='this.blur();' onclick="document.getElementById('div_ft8.1').style.display = 'none' " >
           [x]</a>
        </div>
        <pre>
        
ft8.1: Traceback (most recent call last):
  File "D:\Python34\lib\site-packages\selenium\webdriver\common\service.py", line 64, in start
    stdout=self.log_file, stderr=self.log_file)
  File "D:\Python34\lib\subprocess.py", line 859, in __init__
    restore_signals, start_new_session)
  File "D:\Python34\lib\subprocess.py", line 1112, in _execute_child
    startupinfo)
FileNotFoundError: [WinError 2] 系统找不到指定的文件。

During handling of the above exception, another exception occurred:

Traceback (most recent call last):
  File "E:\hannn\download5\models\myunit.py", line 12, in setUp
    self.driver = webdriver.Chrome()
  File "D:\Python34\lib\site-packages\selenium\webdriver\chrome\webdriver.py", line 62, in __init__
    self.service.start()
  File "D:\Python34\lib\site-packages\selenium\webdriver\common\service.py", line 71, in start
    os.path.basename(self.path), self.start_error_message)
selenium.common.exceptions.WebDriverException: Message: 'chromedriver' executable needs to be in PATH. Please see https://sites.google.com/a/chromium.org/chromedriver/home

Traceback (most recent call last):
  File "D:\Python34\lib\site-packages\selenium\webdriver\common\service.py", line 64, in start
    stdout=self.log_file, stderr=self.log_file)
  File "D:\Python34\lib\subprocess.py", line 859, in __init__
    restore_signals, start_new_session)
  File "D:\Python34\lib\subprocess.py", line 1112, in _execute_child
    startupinfo)
FileNotFoundError: [WinError 2] 系统找不到指定的文件。

During handling of the above exception, another exception occurred:

Traceback (most recent call last):
  File "E:\hannn\download5\models\myunit.py", line 12, in setUp
    self.driver = webdriver.Chrome()
  File "D:\Python34\lib\site-packages\selenium\webdriver\chrome\webdriver.py", line 62, in __init__
    self.service.start()
  File "D:\Python34\lib\site-packages\selenium\webdriver\common\service.py", line 71, in start
    os.path.basename(self.path), self.start_error_message)
selenium.common.exceptions.WebDriverException: Message: 'chromedriver' executable needs to be in PATH. Please see https://sites.google.com/a/chromium.org/chromedriver/home



        </pre>
    </div>
    <!--css div popup end-->

    </td>
</tr>

<tr id='ft8.2' class='none'>
    <td class='errorCase'><div class='testcase'>test_downloady_vip: 页面VIP按钮</div></td>
    <td colspan='5' align='center'>

    <!--css div popup start-->
    <a class="popup_link" onfocus='this.blur();' href="javascript:showTestDetail('div_ft8.2')" >
        error</a>

    <div id='div_ft8.2' class="popup_window">
        <div style='text-align: right; color:red;cursor:pointer'>
        <a onfocus='this.blur();' onclick="document.getElementById('div_ft8.2').style.display = 'none' " >
           [x]</a>
        </div>
        <pre>
        
ft8.2: Traceback (most recent call last):
  File "D:\Python34\lib\site-packages\selenium\webdriver\common\service.py", line 64, in start
    stdout=self.log_file, stderr=self.log_file)
  File "D:\Python34\lib\subprocess.py", line 859, in __init__
    restore_signals, start_new_session)
  File "D:\Python34\lib\subprocess.py", line 1112, in _execute_child
    startupinfo)
FileNotFoundError: [WinError 2] 系统找不到指定的文件。

During handling of the above exception, another exception occurred:

Traceback (most recent call last):
  File "E:\hannn\download5\models\myunit.py", line 12, in setUp
    self.driver = webdriver.Chrome()
  File "D:\Python34\lib\site-packages\selenium\webdriver\chrome\webdriver.py", line 62, in __init__
    self.service.start()
  File "D:\Python34\lib\site-packages\selenium\webdriver\common\service.py", line 71, in start
    os.path.basename(self.path), self.start_error_message)
selenium.common.exceptions.WebDriverException: Message: 'chromedriver' executable needs to be in PATH. Please see https://sites.google.com/a/chromium.org/chromedriver/home

Traceback (most recent call last):
  File "D:\Python34\lib\site-packages\selenium\webdriver\common\service.py", line 64, in start
    stdout=self.log_file, stderr=self.log_file)
  File "D:\Python34\lib\subprocess.py", line 859, in __init__
    restore_signals, start_new_session)
  File "D:\Python34\lib\subprocess.py", line 1112, in _execute_child
    startupinfo)
FileNotFoundError: [WinError 2] 系统找不到指定的文件。

During handling of the above exception, another exception occurred:

Traceback (most recent call last):
  File "E:\hannn\download5\models\myunit.py", line 12, in setUp
    self.driver = webdriver.Chrome()
  File "D:\Python34\lib\site-packages\selenium\webdriver\chrome\webdriver.py", line 62, in __init__
    self.service.start()
  File "D:\Python34\lib\site-packages\selenium\webdriver\common\service.py", line 71, in start
    os.path.basename(self.path), self.start_error_message)
selenium.common.exceptions.WebDriverException: Message: 'chromedriver' executable needs to be in PATH. Please see https://sites.google.com/a/chromium.org/chromedriver/home



        </pre>
    </div>
    <!--css div popup end-->

    </td>
</tr>

<tr class='errorClass'>
    <td>test_case.follow_case.Follow:  关注 </td>
    <td>2</td>
    <td>0</td>
    <td>0</td>
    <td>2</td>
    <td><a href="javascript:showClassDetail('c9',2)">Detail</a></td>
</tr>

<tr id='ft9.1' class='none'>
    <td class='errorCase'><div class='testcase'>test_follow: 关注</div></td>
    <td colspan='5' align='center'>

    <!--css div popup start-->
    <a class="popup_link" onfocus='this.blur();' href="javascript:showTestDetail('div_ft9.1')" >
        error</a>

    <div id='div_ft9.1' class="popup_window">
        <div style='text-align: right; color:red;cursor:pointer'>
        <a onfocus='this.blur();' onclick="document.getElementById('div_ft9.1').style.display = 'none' " >
           [x]</a>
        </div>
        <pre>
        
ft9.1: Traceback (most recent call last):
  File "D:\Python34\lib\site-packages\selenium\webdriver\common\service.py", line 64, in start
    stdout=self.log_file, stderr=self.log_file)
  File "D:\Python34\lib\subprocess.py", line 859, in __init__
    restore_signals, start_new_session)
  File "D:\Python34\lib\subprocess.py", line 1112, in _execute_child
    startupinfo)
FileNotFoundError: [WinError 2] 系统找不到指定的文件。

During handling of the above exception, another exception occurred:

Traceback (most recent call last):
  File "E:\hannn\download5\models\myunit.py", line 12, in setUp
    self.driver = webdriver.Chrome()
  File "D:\Python34\lib\site-packages\selenium\webdriver\chrome\webdriver.py", line 62, in __init__
    self.service.start()
  File "D:\Python34\lib\site-packages\selenium\webdriver\common\service.py", line 71, in start
    os.path.basename(self.path), self.start_error_message)
selenium.common.exceptions.WebDriverException: Message: 'chromedriver' executable needs to be in PATH. Please see https://sites.google.com/a/chromium.org/chromedriver/home

Traceback (most recent call last):
  File "D:\Python34\lib\site-packages\selenium\webdriver\common\service.py", line 64, in start
    stdout=self.log_file, stderr=self.log_file)
  File "D:\Python34\lib\subprocess.py", line 859, in __init__
    restore_signals, start_new_session)
  File "D:\Python34\lib\subprocess.py", line 1112, in _execute_child
    startupinfo)
FileNotFoundError: [WinError 2] 系统找不到指定的文件。

During handling of the above exception, another exception occurred:

Traceback (most recent call last):
  File "E:\hannn\download5\models\myunit.py", line 12, in setUp
    self.driver = webdriver.Chrome()
  File "D:\Python34\lib\site-packages\selenium\webdriver\chrome\webdriver.py", line 62, in __init__
    self.service.start()
  File "D:\Python34\lib\site-packages\selenium\webdriver\common\service.py", line 71, in start
    os.path.basename(self.path), self.start_error_message)
selenium.common.exceptions.WebDriverException: Message: 'chromedriver' executable needs to be in PATH. Please see https://sites.google.com/a/chromium.org/chromedriver/home



        </pre>
    </div>
    <!--css div popup end-->

    </td>
</tr>

<tr id='ft9.2' class='none'>
    <td class='errorCase'><div class='testcase'>test_not_follow: 取消关注</div></td>
    <td colspan='5' align='center'>

    <!--css div popup start-->
    <a class="popup_link" onfocus='this.blur();' href="javascript:showTestDetail('div_ft9.2')" >
        error</a>

    <div id='div_ft9.2' class="popup_window">
        <div style='text-align: right; color:red;cursor:pointer'>
        <a onfocus='this.blur();' onclick="document.getElementById('div_ft9.2').style.display = 'none' " >
           [x]</a>
        </div>
        <pre>
        
ft9.2: Traceback (most recent call last):
  File "D:\Python34\lib\site-packages\selenium\webdriver\common\service.py", line 64, in start
    stdout=self.log_file, stderr=self.log_file)
  File "D:\Python34\lib\subprocess.py", line 859, in __init__
    restore_signals, start_new_session)
  File "D:\Python34\lib\subprocess.py", line 1112, in _execute_child
    startupinfo)
FileNotFoundError: [WinError 2] 系统找不到指定的文件。

During handling of the above exception, another exception occurred:

Traceback (most recent call last):
  File "E:\hannn\download5\models\myunit.py", line 12, in setUp
    self.driver = webdriver.Chrome()
  File "D:\Python34\lib\site-packages\selenium\webdriver\chrome\webdriver.py", line 62, in __init__
    self.service.start()
  File "D:\Python34\lib\site-packages\selenium\webdriver\common\service.py", line 71, in start
    os.path.basename(self.path), self.start_error_message)
selenium.common.exceptions.WebDriverException: Message: 'chromedriver' executable needs to be in PATH. Please see https://sites.google.com/a/chromium.org/chromedriver/home

Traceback (most recent call last):
  File "D:\Python34\lib\site-packages\selenium\webdriver\common\service.py", line 64, in start
    stdout=self.log_file, stderr=self.log_file)
  File "D:\Python34\lib\subprocess.py", line 859, in __init__
    restore_signals, start_new_session)
  File "D:\Python34\lib\subprocess.py", line 1112, in _execute_child
    startupinfo)
FileNotFoundError: [WinError 2] 系统找不到指定的文件。

During handling of the above exception, another exception occurred:

Traceback (most recent call last):
  File "E:\hannn\download5\models\myunit.py", line 12, in setUp
    self.driver = webdriver.Chrome()
  File "D:\Python34\lib\site-packages\selenium\webdriver\chrome\webdriver.py", line 62, in __init__
    self.service.start()
  File "D:\Python34\lib\site-packages\selenium\webdriver\common\service.py", line 71, in start
    os.path.basename(self.path), self.start_error_message)
selenium.common.exceptions.WebDriverException: Message: 'chromedriver' executable needs to be in PATH. Please see https://sites.google.com/a/chromium.org/chromedriver/home



        </pre>
    </div>
    <!--css div popup end-->

    </td>
</tr>

<tr class='errorClass'>
    <td>test_case.rank_case.Rank:  排行榜 </td>
    <td>1</td>
    <td>0</td>
    <td>0</td>
    <td>1</td>
    <td><a href="javascript:showClassDetail('c10',1)">Detail</a></td>
</tr>

<tr id='ft10.1' class='none'>
    <td class='errorCase'><div class='testcase'>test_rank: 排行榜</div></td>
    <td colspan='5' align='center'>

    <!--css div popup start-->
    <a class="popup_link" onfocus='this.blur();' href="javascript:showTestDetail('div_ft10.1')" >
        error</a>

    <div id='div_ft10.1' class="popup_window">
        <div style='text-align: right; color:red;cursor:pointer'>
        <a onfocus='this.blur();' onclick="document.getElementById('div_ft10.1').style.display = 'none' " >
           [x]</a>
        </div>
        <pre>
        
ft10.1: Traceback (most recent call last):
  File "D:\Python34\lib\site-packages\selenium\webdriver\common\service.py", line 64, in start
    stdout=self.log_file, stderr=self.log_file)
  File "D:\Python34\lib\subprocess.py", line 859, in __init__
    restore_signals, start_new_session)
  File "D:\Python34\lib\subprocess.py", line 1112, in _execute_child
    startupinfo)
FileNotFoundError: [WinError 2] 系统找不到指定的文件。

During handling of the above exception, another exception occurred:

Traceback (most recent call last):
  File "E:\hannn\download5\models\myunit.py", line 12, in setUp
    self.driver = webdriver.Chrome()
  File "D:\Python34\lib\site-packages\selenium\webdriver\chrome\webdriver.py", line 62, in __init__
    self.service.start()
  File "D:\Python34\lib\site-packages\selenium\webdriver\common\service.py", line 71, in start
    os.path.basename(self.path), self.start_error_message)
selenium.common.exceptions.WebDriverException: Message: 'chromedriver' executable needs to be in PATH. Please see https://sites.google.com/a/chromium.org/chromedriver/home

Traceback (most recent call last):
  File "D:\Python34\lib\site-packages\selenium\webdriver\common\service.py", line 64, in start
    stdout=self.log_file, stderr=self.log_file)
  File "D:\Python34\lib\subprocess.py", line 859, in __init__
    restore_signals, start_new_session)
  File "D:\Python34\lib\subprocess.py", line 1112, in _execute_child
    startupinfo)
FileNotFoundError: [WinError 2] 系统找不到指定的文件。

During handling of the above exception, another exception occurred:

Traceback (most recent call last):
  File "E:\hannn\download5\models\myunit.py", line 12, in setUp
    self.driver = webdriver.Chrome()
  File "D:\Python34\lib\site-packages\selenium\webdriver\chrome\webdriver.py", line 62, in __init__
    self.service.start()
  File "D:\Python34\lib\site-packages\selenium\webdriver\common\service.py", line 71, in start
    os.path.basename(self.path), self.start_error_message)
selenium.common.exceptions.WebDriverException: Message: 'chromedriver' executable needs to be in PATH. Please see https://sites.google.com/a/chromium.org/chromedriver/home



        </pre>
    </div>
    <!--css div popup end-->

    </td>
</tr>

<tr class='errorClass'>
    <td>test_case.album_case.Album:  专辑管理-编辑 </td>
    <td>1</td>
    <td>0</td>
    <td>0</td>
    <td>1</td>
    <td><a href="javascript:showClassDetail('c11',1)">Detail</a></td>
</tr>

<tr id='ft11.1' class='none'>
    <td class='errorCase'><div class='testcase'>test_album: 专辑管理</div></td>
    <td colspan='5' align='center'>

    <!--css div popup start-->
    <a class="popup_link" onfocus='this.blur();' href="javascript:showTestDetail('div_ft11.1')" >
        error</a>

    <div id='div_ft11.1' class="popup_window">
        <div style='text-align: right; color:red;cursor:pointer'>
        <a onfocus='this.blur();' onclick="document.getElementById('div_ft11.1').style.display = 'none' " >
           [x]</a>
        </div>
        <pre>
        
ft11.1: Traceback (most recent call last):
  File "D:\Python34\lib\site-packages\selenium\webdriver\common\service.py", line 64, in start
    stdout=self.log_file, stderr=self.log_file)
  File "D:\Python34\lib\subprocess.py", line 859, in __init__
    restore_signals, start_new_session)
  File "D:\Python34\lib\subprocess.py", line 1112, in _execute_child
    startupinfo)
FileNotFoundError: [WinError 2] 系统找不到指定的文件。

During handling of the above exception, another exception occurred:

Traceback (most recent call last):
  File "E:\hannn\download5\models\myunit.py", line 12, in setUp
    self.driver = webdriver.Chrome()
  File "D:\Python34\lib\site-packages\selenium\webdriver\chrome\webdriver.py", line 62, in __init__
    self.service.start()
  File "D:\Python34\lib\site-packages\selenium\webdriver\common\service.py", line 71, in start
    os.path.basename(self.path), self.start_error_message)
selenium.common.exceptions.WebDriverException: Message: 'chromedriver' executable needs to be in PATH. Please see https://sites.google.com/a/chromium.org/chromedriver/home

Traceback (most recent call last):
  File "D:\Python34\lib\site-packages\selenium\webdriver\common\service.py", line 64, in start
    stdout=self.log_file, stderr=self.log_file)
  File "D:\Python34\lib\subprocess.py", line 859, in __init__
    restore_signals, start_new_session)
  File "D:\Python34\lib\subprocess.py", line 1112, in _execute_child
    startupinfo)
FileNotFoundError: [WinError 2] 系统找不到指定的文件。

During handling of the above exception, another exception occurred:

Traceback (most recent call last):
  File "E:\hannn\download5\models\myunit.py", line 12, in setUp
    self.driver = webdriver.Chrome()
  File "D:\Python34\lib\site-packages\selenium\webdriver\chrome\webdriver.py", line 62, in __init__
    self.service.start()
  File "D:\Python34\lib\site-packages\selenium\webdriver\common\service.py", line 71, in start
    os.path.basename(self.path), self.start_error_message)
selenium.common.exceptions.WebDriverException: Message: 'chromedriver' executable needs to be in PATH. Please see https://sites.google.com/a/chromium.org/chromedriver/home



        </pre>
    </div>
    <!--css div popup end-->

    </td>
</tr>

<tr class='errorClass'>
    <td>test_case.jp_album_case.Jpalbum:  精品专辑 </td>
    <td>3</td>
    <td>0</td>
    <td>0</td>
    <td>3</td>
    <td><a href="javascript:showClassDetail('c12',3)">Detail</a></td>
</tr>

<tr id='ft12.1' class='none'>
    <td class='errorCase'><div class='testcase'>test_album_gx: 专辑贡献榜</div></td>
    <td colspan='5' align='center'>

    <!--css div popup start-->
    <a class="popup_link" onfocus='this.blur();' href="javascript:showTestDetail('div_ft12.1')" >
        error</a>

    <div id='div_ft12.1' class="popup_window">
        <div style='text-align: right; color:red;cursor:pointer'>
        <a onfocus='this.blur();' onclick="document.getElementById('div_ft12.1').style.display = 'none' " >
           [x]</a>
        </div>
        <pre>
        
ft12.1: Traceback (most recent call last):
  File "D:\Python34\lib\site-packages\selenium\webdriver\common\service.py", line 64, in start
    stdout=self.log_file, stderr=self.log_file)
  File "D:\Python34\lib\subprocess.py", line 859, in __init__
    restore_signals, start_new_session)
  File "D:\Python34\lib\subprocess.py", line 1112, in _execute_child
    startupinfo)
FileNotFoundError: [WinError 2] 系统找不到指定的文件。

During handling of the above exception, another exception occurred:

Traceback (most recent call last):
  File "E:\hannn\download5\models\myunit.py", line 12, in setUp
    self.driver = webdriver.Chrome()
  File "D:\Python34\lib\site-packages\selenium\webdriver\chrome\webdriver.py", line 62, in __init__
    self.service.start()
  File "D:\Python34\lib\site-packages\selenium\webdriver\common\service.py", line 71, in start
    os.path.basename(self.path), self.start_error_message)
selenium.common.exceptions.WebDriverException: Message: 'chromedriver' executable needs to be in PATH. Please see https://sites.google.com/a/chromium.org/chromedriver/home

Traceback (most recent call last):
  File "D:\Python34\lib\site-packages\selenium\webdriver\common\service.py", line 64, in start
    stdout=self.log_file, stderr=self.log_file)
  File "D:\Python34\lib\subprocess.py", line 859, in __init__
    restore_signals, start_new_session)
  File "D:\Python34\lib\subprocess.py", line 1112, in _execute_child
    startupinfo)
FileNotFoundError: [WinError 2] 系统找不到指定的文件。

During handling of the above exception, another exception occurred:

Traceback (most recent call last):
  File "E:\hannn\download5\models\myunit.py", line 12, in setUp
    self.driver = webdriver.Chrome()
  File "D:\Python34\lib\site-packages\selenium\webdriver\chrome\webdriver.py", line 62, in __init__
    self.service.start()
  File "D:\Python34\lib\site-packages\selenium\webdriver\common\service.py", line 71, in start
    os.path.basename(self.path), self.start_error_message)
selenium.common.exceptions.WebDriverException: Message: 'chromedriver' executable needs to be in PATH. Please see https://sites.google.com/a/chromium.org/chromedriver/home



        </pre>
    </div>
    <!--css div popup end-->

    </td>
</tr>

<tr id='ft12.2' class='none'>
    <td class='errorCase'><div class='testcase'>test_album_jp: 顶部图片切换，点击用户名跳转</div></td>
    <td colspan='5' align='center'>

    <!--css div popup start-->
    <a class="popup_link" onfocus='this.blur();' href="javascript:showTestDetail('div_ft12.2')" >
        error</a>

    <div id='div_ft12.2' class="popup_window">
        <div style='text-align: right; color:red;cursor:pointer'>
        <a onfocus='this.blur();' onclick="document.getElementById('div_ft12.2').style.display = 'none' " >
           [x]</a>
        </div>
        <pre>
        
ft12.2: Traceback (most recent call last):
  File "D:\Python34\lib\site-packages\selenium\webdriver\common\service.py", line 64, in start
    stdout=self.log_file, stderr=self.log_file)
  File "D:\Python34\lib\subprocess.py", line 859, in __init__
    restore_signals, start_new_session)
  File "D:\Python34\lib\subprocess.py", line 1112, in _execute_child
    startupinfo)
FileNotFoundError: [WinError 2] 系统找不到指定的文件。

During handling of the above exception, another exception occurred:

Traceback (most recent call last):
  File "E:\hannn\download5\models\myunit.py", line 12, in setUp
    self.driver = webdriver.Chrome()
  File "D:\Python34\lib\site-packages\selenium\webdriver\chrome\webdriver.py", line 62, in __init__
    self.service.start()
  File "D:\Python34\lib\site-packages\selenium\webdriver\common\service.py", line 71, in start
    os.path.basename(self.path), self.start_error_message)
selenium.common.exceptions.WebDriverException: Message: 'chromedriver' executable needs to be in PATH. Please see https://sites.google.com/a/chromium.org/chromedriver/home

Traceback (most recent call last):
  File "D:\Python34\lib\site-packages\selenium\webdriver\common\service.py", line 64, in start
    stdout=self.log_file, stderr=self.log_file)
  File "D:\Python34\lib\subprocess.py", line 859, in __init__
    restore_signals, start_new_session)
  File "D:\Python34\lib\subprocess.py", line 1112, in _execute_child
    startupinfo)
FileNotFoundError: [WinError 2] 系统找不到指定的文件。

During handling of the above exception, another exception occurred:

Traceback (most recent call last):
  File "E:\hannn\download5\models\myunit.py", line 12, in setUp
    self.driver = webdriver.Chrome()
  File "D:\Python34\lib\site-packages\selenium\webdriver\chrome\webdriver.py", line 62, in __init__
    self.service.start()
  File "D:\Python34\lib\site-packages\selenium\webdriver\common\service.py", line 71, in start
    os.path.basename(self.path), self.start_error_message)
selenium.common.exceptions.WebDriverException: Message: 'chromedriver' executable needs to be in PATH. Please see https://sites.google.com/a/chromium.org/chromedriver/home



        </pre>
    </div>
    <!--css div popup end-->

    </td>
</tr>

<tr id='ft12.3' class='none'>
    <td class='errorCase'><div class='testcase'>test_album_list: 专辑列表-点击用户头像或用户名跳转到个人中心</div></td>
    <td colspan='5' align='center'>

    <!--css div popup start-->
    <a class="popup_link" onfocus='this.blur();' href="javascript:showTestDetail('div_ft12.3')" >
        error</a>

    <div id='div_ft12.3' class="popup_window">
        <div style='text-align: right; color:red;cursor:pointer'>
        <a onfocus='this.blur();' onclick="document.getElementById('div_ft12.3').style.display = 'none' " >
           [x]</a>
        </div>
        <pre>
        
ft12.3: Traceback (most recent call last):
  File "D:\Python34\lib\site-packages\selenium\webdriver\common\service.py", line 64, in start
    stdout=self.log_file, stderr=self.log_file)
  File "D:\Python34\lib\subprocess.py", line 859, in __init__
    restore_signals, start_new_session)
  File "D:\Python34\lib\subprocess.py", line 1112, in _execute_child
    startupinfo)
FileNotFoundError: [WinError 2] 系统找不到指定的文件。

During handling of the above exception, another exception occurred:

Traceback (most recent call last):
  File "E:\hannn\download5\models\myunit.py", line 12, in setUp
    self.driver = webdriver.Chrome()
  File "D:\Python34\lib\site-packages\selenium\webdriver\chrome\webdriver.py", line 62, in __init__
    self.service.start()
  File "D:\Python34\lib\site-packages\selenium\webdriver\common\service.py", line 71, in start
    os.path.basename(self.path), self.start_error_message)
selenium.common.exceptions.WebDriverException: Message: 'chromedriver' executable needs to be in PATH. Please see https://sites.google.com/a/chromium.org/chromedriver/home

Traceback (most recent call last):
  File "D:\Python34\lib\site-packages\selenium\webdriver\common\service.py", line 64, in start
    stdout=self.log_file, stderr=self.log_file)
  File "D:\Python34\lib\subprocess.py", line 859, in __init__
    restore_signals, start_new_session)
  File "D:\Python34\lib\subprocess.py", line 1112, in _execute_child
    startupinfo)
FileNotFoundError: [WinError 2] 系统找不到指定的文件。

During handling of the above exception, another exception occurred:

Traceback (most recent call last):
  File "E:\hannn\download5\models\myunit.py", line 12, in setUp
    self.driver = webdriver.Chrome()
  File "D:\Python34\lib\site-packages\selenium\webdriver\chrome\webdriver.py", line 62, in __init__
    self.service.start()
  File "D:\Python34\lib\site-packages\selenium\webdriver\common\service.py", line 71, in start
    os.path.basename(self.path), self.start_error_message)
selenium.common.exceptions.WebDriverException: Message: 'chromedriver' executable needs to be in PATH. Please see https://sites.google.com/a/chromium.org/chromedriver/home



        </pre>
    </div>
    <!--css div popup end-->

    </td>
</tr>

<tr id='total_row'>
    <td>Total</td>
    <td>26</td>
    <td>0</td>
    <td>0</td>
    <td>26</td>
    <td>&nbsp;</td>
</tr>
</table>

<div id='ending'>&nbsp;</div>

</body>
</html>
